{
 "cells": [
  {
   "cell_type": "code",
   "execution_count": 1,
   "metadata": {},
   "outputs": [],
   "source": [
    "import tensorflow as tf\n",
    "from tensorflow import keras"
   ]
  },
  {
   "cell_type": "code",
   "execution_count": 2,
   "metadata": {},
   "outputs": [],
   "source": [
    "model = keras.models.load_model('xception_v4_1_08_0.883.h5')"
   ]
  },
  {
   "cell_type": "code",
   "execution_count": 3,
   "metadata": {},
   "outputs": [],
   "source": [
    "from tensorflow.keras.preprocessing.image import ImageDataGenerator\n",
    "from tensorflow.keras.preprocessing.image import load_img\n",
    "from tensorflow.keras.applications.xception import preprocess_input"
   ]
  },
  {
   "cell_type": "code",
   "execution_count": 18,
   "metadata": {},
   "outputs": [
    {
     "name": "stdout",
     "output_type": "stream",
     "text": [
      "Found 341 images belonging to 10 classes.\n"
     ]
    }
   ],
   "source": [
    "test_gen = ImageDataGenerator(preprocessing_function= preprocess_input)\n",
    "\n",
    "test_ds = test_gen.flow_from_directory(\n",
    "    './clothing-dataset-small-master/validation',\n",
    "    target_size = (150,150),\n",
    "    batch_size = 16,\n",
    "    shuffle = False\n",
    ")"
   ]
  },
  {
   "cell_type": "code",
   "execution_count": 19,
   "metadata": {},
   "outputs": [
    {
     "ename": "UnimplementedError",
     "evalue": "Graph execution error:\n\nDetected at node 'model_7/xception/block1_conv1/Conv2D' defined at (most recent call last):\n    File \"c:\\Users\\tuto\\AppData\\Local\\Programs\\Python\\Python37\\lib\\runpy.py\", line 193, in _run_module_as_main\n      \"__main__\", mod_spec)\n    File \"c:\\Users\\tuto\\AppData\\Local\\Programs\\Python\\Python37\\lib\\runpy.py\", line 85, in _run_code\n      exec(code, run_globals)\n    File \"C:\\Users\\tuto\\AppData\\Roaming\\Python\\Python37\\site-packages\\ipykernel_launcher.py\", line 16, in <module>\n      app.launch_new_instance()\n    File \"C:\\Users\\tuto\\AppData\\Roaming\\Python\\Python37\\site-packages\\traitlets\\config\\application.py\", line 664, in launch_instance\n      app.start()\n    File \"C:\\Users\\tuto\\AppData\\Roaming\\Python\\Python37\\site-packages\\ipykernel\\kernelapp.py\", line 597, in start\n      self.io_loop.start()\n    File \"C:\\Users\\tuto\\AppData\\Roaming\\Python\\Python37\\site-packages\\tornado\\platform\\asyncio.py\", line 149, in start\n      self.asyncio_loop.run_forever()\n    File \"c:\\Users\\tuto\\AppData\\Local\\Programs\\Python\\Python37\\lib\\asyncio\\base_events.py\", line 538, in run_forever\n      self._run_once()\n    File \"c:\\Users\\tuto\\AppData\\Local\\Programs\\Python\\Python37\\lib\\asyncio\\base_events.py\", line 1782, in _run_once\n      handle._run()\n    File \"c:\\Users\\tuto\\AppData\\Local\\Programs\\Python\\Python37\\lib\\asyncio\\events.py\", line 88, in _run\n      self._context.run(self._callback, *self._args)\n    File \"C:\\Users\\tuto\\AppData\\Roaming\\Python\\Python37\\site-packages\\tornado\\ioloop.py\", line 690, in <lambda>\n      lambda f: self._run_callback(functools.partial(callback, future))\n    File \"C:\\Users\\tuto\\AppData\\Roaming\\Python\\Python37\\site-packages\\tornado\\ioloop.py\", line 743, in _run_callback\n      ret = callback()\n    File \"C:\\Users\\tuto\\AppData\\Roaming\\Python\\Python37\\site-packages\\tornado\\gen.py\", line 787, in inner\n      self.run()\n    File \"C:\\Users\\tuto\\AppData\\Roaming\\Python\\Python37\\site-packages\\tornado\\gen.py\", line 748, in run\n      yielded = self.gen.send(value)\n    File \"C:\\Users\\tuto\\AppData\\Roaming\\Python\\Python37\\site-packages\\ipykernel\\kernelbase.py\", line 365, in process_one\n      yield gen.maybe_future(dispatch(*args))\n    File \"C:\\Users\\tuto\\AppData\\Roaming\\Python\\Python37\\site-packages\\tornado\\gen.py\", line 209, in wrapper\n      yielded = next(result)\n    File \"C:\\Users\\tuto\\AppData\\Roaming\\Python\\Python37\\site-packages\\ipykernel\\kernelbase.py\", line 268, in dispatch_shell\n      yield gen.maybe_future(handler(stream, idents, msg))\n    File \"C:\\Users\\tuto\\AppData\\Roaming\\Python\\Python37\\site-packages\\tornado\\gen.py\", line 209, in wrapper\n      yielded = next(result)\n    File \"C:\\Users\\tuto\\AppData\\Roaming\\Python\\Python37\\site-packages\\ipykernel\\kernelbase.py\", line 545, in execute_request\n      user_expressions, allow_stdin,\n    File \"C:\\Users\\tuto\\AppData\\Roaming\\Python\\Python37\\site-packages\\tornado\\gen.py\", line 209, in wrapper\n      yielded = next(result)\n    File \"C:\\Users\\tuto\\AppData\\Roaming\\Python\\Python37\\site-packages\\ipykernel\\ipkernel.py\", line 300, in do_execute\n      res = shell.run_cell(code, store_history=store_history, silent=silent)\n    File \"C:\\Users\\tuto\\AppData\\Roaming\\Python\\Python37\\site-packages\\ipykernel\\zmqshell.py\", line 536, in run_cell\n      return super(ZMQInteractiveShell, self).run_cell(*args, **kwargs)\n    File \"C:\\Users\\tuto\\AppData\\Roaming\\Python\\Python37\\site-packages\\IPython\\core\\interactiveshell.py\", line 2858, in run_cell\n      raw_cell, store_history, silent, shell_futures)\n    File \"C:\\Users\\tuto\\AppData\\Roaming\\Python\\Python37\\site-packages\\IPython\\core\\interactiveshell.py\", line 2886, in _run_cell\n      return runner(coro)\n    File \"C:\\Users\\tuto\\AppData\\Roaming\\Python\\Python37\\site-packages\\IPython\\core\\async_helpers.py\", line 68, in _pseudo_sync_runner\n      coro.send(None)\n    File \"C:\\Users\\tuto\\AppData\\Roaming\\Python\\Python37\\site-packages\\IPython\\core\\interactiveshell.py\", line 3063, in run_cell_async\n      interactivity=interactivity, compiler=compiler, result=result)\n    File \"C:\\Users\\tuto\\AppData\\Roaming\\Python\\Python37\\site-packages\\IPython\\core\\interactiveshell.py\", line 3254, in run_ast_nodes\n      if (await self.run_code(code, result,  async_=asy)):\n    File \"C:\\Users\\tuto\\AppData\\Roaming\\Python\\Python37\\site-packages\\IPython\\core\\interactiveshell.py\", line 3331, in run_code\n      exec(code_obj, self.user_global_ns, self.user_ns)\n    File \"<ipython-input-6-cf7953a05327>\", line 1, in <module>\n      model.evaluate(test_ds)\n    File \"c:\\Users\\tuto\\AppData\\Local\\Programs\\Python\\Python37\\lib\\site-packages\\keras\\utils\\traceback_utils.py\", line 65, in error_handler\n      return fn(*args, **kwargs)\n    File \"c:\\Users\\tuto\\AppData\\Local\\Programs\\Python\\Python37\\lib\\site-packages\\keras\\engine\\training.py\", line 1947, in evaluate\n      tmp_logs = self.test_function(iterator)\n    File \"c:\\Users\\tuto\\AppData\\Local\\Programs\\Python\\Python37\\lib\\site-packages\\keras\\engine\\training.py\", line 1727, in test_function\n      return step_function(self, iterator)\n    File \"c:\\Users\\tuto\\AppData\\Local\\Programs\\Python\\Python37\\lib\\site-packages\\keras\\engine\\training.py\", line 1713, in step_function\n      outputs = model.distribute_strategy.run(run_step, args=(data,))\n    File \"c:\\Users\\tuto\\AppData\\Local\\Programs\\Python\\Python37\\lib\\site-packages\\keras\\engine\\training.py\", line 1701, in run_step\n      outputs = model.test_step(data)\n    File \"c:\\Users\\tuto\\AppData\\Local\\Programs\\Python\\Python37\\lib\\site-packages\\keras\\engine\\training.py\", line 1665, in test_step\n      y_pred = self(x, training=False)\n    File \"c:\\Users\\tuto\\AppData\\Local\\Programs\\Python\\Python37\\lib\\site-packages\\keras\\utils\\traceback_utils.py\", line 65, in error_handler\n      return fn(*args, **kwargs)\n    File \"c:\\Users\\tuto\\AppData\\Local\\Programs\\Python\\Python37\\lib\\site-packages\\keras\\engine\\training.py\", line 557, in __call__\n      return super().__call__(*args, **kwargs)\n    File \"c:\\Users\\tuto\\AppData\\Local\\Programs\\Python\\Python37\\lib\\site-packages\\keras\\utils\\traceback_utils.py\", line 65, in error_handler\n      return fn(*args, **kwargs)\n    File \"c:\\Users\\tuto\\AppData\\Local\\Programs\\Python\\Python37\\lib\\site-packages\\keras\\engine\\base_layer.py\", line 1097, in __call__\n      outputs = call_fn(inputs, *args, **kwargs)\n    File \"c:\\Users\\tuto\\AppData\\Local\\Programs\\Python\\Python37\\lib\\site-packages\\keras\\utils\\traceback_utils.py\", line 96, in error_handler\n      return fn(*args, **kwargs)\n    File \"c:\\Users\\tuto\\AppData\\Local\\Programs\\Python\\Python37\\lib\\site-packages\\keras\\engine\\functional.py\", line 510, in call\n      return self._run_internal_graph(inputs, training=training, mask=mask)\n    File \"c:\\Users\\tuto\\AppData\\Local\\Programs\\Python\\Python37\\lib\\site-packages\\keras\\engine\\functional.py\", line 667, in _run_internal_graph\n      outputs = node.layer(*args, **kwargs)\n    File \"c:\\Users\\tuto\\AppData\\Local\\Programs\\Python\\Python37\\lib\\site-packages\\keras\\utils\\traceback_utils.py\", line 65, in error_handler\n      return fn(*args, **kwargs)\n    File \"c:\\Users\\tuto\\AppData\\Local\\Programs\\Python\\Python37\\lib\\site-packages\\keras\\engine\\training.py\", line 557, in __call__\n      return super().__call__(*args, **kwargs)\n    File \"c:\\Users\\tuto\\AppData\\Local\\Programs\\Python\\Python37\\lib\\site-packages\\keras\\utils\\traceback_utils.py\", line 65, in error_handler\n      return fn(*args, **kwargs)\n    File \"c:\\Users\\tuto\\AppData\\Local\\Programs\\Python\\Python37\\lib\\site-packages\\keras\\engine\\base_layer.py\", line 1097, in __call__\n      outputs = call_fn(inputs, *args, **kwargs)\n    File \"c:\\Users\\tuto\\AppData\\Local\\Programs\\Python\\Python37\\lib\\site-packages\\keras\\utils\\traceback_utils.py\", line 96, in error_handler\n      return fn(*args, **kwargs)\n    File \"c:\\Users\\tuto\\AppData\\Local\\Programs\\Python\\Python37\\lib\\site-packages\\keras\\engine\\functional.py\", line 510, in call\n      return self._run_internal_graph(inputs, training=training, mask=mask)\n    File \"c:\\Users\\tuto\\AppData\\Local\\Programs\\Python\\Python37\\lib\\site-packages\\keras\\engine\\functional.py\", line 667, in _run_internal_graph\n      outputs = node.layer(*args, **kwargs)\n    File \"c:\\Users\\tuto\\AppData\\Local\\Programs\\Python\\Python37\\lib\\site-packages\\keras\\utils\\traceback_utils.py\", line 65, in error_handler\n      return fn(*args, **kwargs)\n    File \"c:\\Users\\tuto\\AppData\\Local\\Programs\\Python\\Python37\\lib\\site-packages\\keras\\engine\\base_layer.py\", line 1097, in __call__\n      outputs = call_fn(inputs, *args, **kwargs)\n    File \"c:\\Users\\tuto\\AppData\\Local\\Programs\\Python\\Python37\\lib\\site-packages\\keras\\utils\\traceback_utils.py\", line 96, in error_handler\n      return fn(*args, **kwargs)\n    File \"c:\\Users\\tuto\\AppData\\Local\\Programs\\Python\\Python37\\lib\\site-packages\\keras\\layers\\convolutional\\base_conv.py\", line 283, in call\n      outputs = self.convolution_op(inputs, self.kernel)\n    File \"c:\\Users\\tuto\\AppData\\Local\\Programs\\Python\\Python37\\lib\\site-packages\\keras\\layers\\convolutional\\base_conv.py\", line 262, in convolution_op\n      name=self.__class__.__name__,\nNode: 'model_7/xception/block1_conv1/Conv2D'\nDNN library is not found.\n\t [[{{node model_7/xception/block1_conv1/Conv2D}}]] [Op:__inference_test_function_5324]",
     "output_type": "error",
     "traceback": [
      "\u001b[1;31m---------------------------------------------------------------------------\u001b[0m",
      "\u001b[1;31mUnimplementedError\u001b[0m                        Traceback (most recent call last)",
      "\u001b[1;32m<ipython-input-19-cf7953a05327>\u001b[0m in \u001b[0;36m<module>\u001b[1;34m\u001b[0m\n\u001b[1;32m----> 1\u001b[1;33m \u001b[0mmodel\u001b[0m\u001b[1;33m.\u001b[0m\u001b[0mevaluate\u001b[0m\u001b[1;33m(\u001b[0m\u001b[0mtest_ds\u001b[0m\u001b[1;33m)\u001b[0m\u001b[1;33m\u001b[0m\u001b[1;33m\u001b[0m\u001b[0m\n\u001b[0m",
      "\u001b[1;32mc:\\Users\\tuto\\AppData\\Local\\Programs\\Python\\Python37\\lib\\site-packages\\keras\\utils\\traceback_utils.py\u001b[0m in \u001b[0;36merror_handler\u001b[1;34m(*args, **kwargs)\u001b[0m\n\u001b[0;32m     68\u001b[0m             \u001b[1;31m# To get the full stack trace, call:\u001b[0m\u001b[1;33m\u001b[0m\u001b[1;33m\u001b[0m\u001b[1;33m\u001b[0m\u001b[0m\n\u001b[0;32m     69\u001b[0m             \u001b[1;31m# `tf.debugging.disable_traceback_filtering()`\u001b[0m\u001b[1;33m\u001b[0m\u001b[1;33m\u001b[0m\u001b[1;33m\u001b[0m\u001b[0m\n\u001b[1;32m---> 70\u001b[1;33m             \u001b[1;32mraise\u001b[0m \u001b[0me\u001b[0m\u001b[1;33m.\u001b[0m\u001b[0mwith_traceback\u001b[0m\u001b[1;33m(\u001b[0m\u001b[0mfiltered_tb\u001b[0m\u001b[1;33m)\u001b[0m \u001b[1;32mfrom\u001b[0m \u001b[1;32mNone\u001b[0m\u001b[1;33m\u001b[0m\u001b[1;33m\u001b[0m\u001b[0m\n\u001b[0m\u001b[0;32m     71\u001b[0m         \u001b[1;32mfinally\u001b[0m\u001b[1;33m:\u001b[0m\u001b[1;33m\u001b[0m\u001b[1;33m\u001b[0m\u001b[0m\n\u001b[0;32m     72\u001b[0m             \u001b[1;32mdel\u001b[0m \u001b[0mfiltered_tb\u001b[0m\u001b[1;33m\u001b[0m\u001b[1;33m\u001b[0m\u001b[0m\n",
      "\u001b[1;32mc:\\Users\\tuto\\AppData\\Local\\Programs\\Python\\Python37\\lib\\site-packages\\tensorflow\\python\\eager\\execute.py\u001b[0m in \u001b[0;36mquick_execute\u001b[1;34m(op_name, num_outputs, inputs, attrs, ctx, name)\u001b[0m\n\u001b[0;32m     53\u001b[0m     \u001b[0mctx\u001b[0m\u001b[1;33m.\u001b[0m\u001b[0mensure_initialized\u001b[0m\u001b[1;33m(\u001b[0m\u001b[1;33m)\u001b[0m\u001b[1;33m\u001b[0m\u001b[1;33m\u001b[0m\u001b[0m\n\u001b[0;32m     54\u001b[0m     tensors = pywrap_tfe.TFE_Py_Execute(ctx._handle, device_name, op_name,\n\u001b[1;32m---> 55\u001b[1;33m                                         inputs, attrs, num_outputs)\n\u001b[0m\u001b[0;32m     56\u001b[0m   \u001b[1;32mexcept\u001b[0m \u001b[0mcore\u001b[0m\u001b[1;33m.\u001b[0m\u001b[0m_NotOkStatusException\u001b[0m \u001b[1;32mas\u001b[0m \u001b[0me\u001b[0m\u001b[1;33m:\u001b[0m\u001b[1;33m\u001b[0m\u001b[1;33m\u001b[0m\u001b[0m\n\u001b[0;32m     57\u001b[0m     \u001b[1;32mif\u001b[0m \u001b[0mname\u001b[0m \u001b[1;32mis\u001b[0m \u001b[1;32mnot\u001b[0m \u001b[1;32mNone\u001b[0m\u001b[1;33m:\u001b[0m\u001b[1;33m\u001b[0m\u001b[1;33m\u001b[0m\u001b[0m\n",
      "\u001b[1;31mUnimplementedError\u001b[0m: Graph execution error:\n\nDetected at node 'model_7/xception/block1_conv1/Conv2D' defined at (most recent call last):\n    File \"c:\\Users\\tuto\\AppData\\Local\\Programs\\Python\\Python37\\lib\\runpy.py\", line 193, in _run_module_as_main\n      \"__main__\", mod_spec)\n    File \"c:\\Users\\tuto\\AppData\\Local\\Programs\\Python\\Python37\\lib\\runpy.py\", line 85, in _run_code\n      exec(code, run_globals)\n    File \"C:\\Users\\tuto\\AppData\\Roaming\\Python\\Python37\\site-packages\\ipykernel_launcher.py\", line 16, in <module>\n      app.launch_new_instance()\n    File \"C:\\Users\\tuto\\AppData\\Roaming\\Python\\Python37\\site-packages\\traitlets\\config\\application.py\", line 664, in launch_instance\n      app.start()\n    File \"C:\\Users\\tuto\\AppData\\Roaming\\Python\\Python37\\site-packages\\ipykernel\\kernelapp.py\", line 597, in start\n      self.io_loop.start()\n    File \"C:\\Users\\tuto\\AppData\\Roaming\\Python\\Python37\\site-packages\\tornado\\platform\\asyncio.py\", line 149, in start\n      self.asyncio_loop.run_forever()\n    File \"c:\\Users\\tuto\\AppData\\Local\\Programs\\Python\\Python37\\lib\\asyncio\\base_events.py\", line 538, in run_forever\n      self._run_once()\n    File \"c:\\Users\\tuto\\AppData\\Local\\Programs\\Python\\Python37\\lib\\asyncio\\base_events.py\", line 1782, in _run_once\n      handle._run()\n    File \"c:\\Users\\tuto\\AppData\\Local\\Programs\\Python\\Python37\\lib\\asyncio\\events.py\", line 88, in _run\n      self._context.run(self._callback, *self._args)\n    File \"C:\\Users\\tuto\\AppData\\Roaming\\Python\\Python37\\site-packages\\tornado\\ioloop.py\", line 690, in <lambda>\n      lambda f: self._run_callback(functools.partial(callback, future))\n    File \"C:\\Users\\tuto\\AppData\\Roaming\\Python\\Python37\\site-packages\\tornado\\ioloop.py\", line 743, in _run_callback\n      ret = callback()\n    File \"C:\\Users\\tuto\\AppData\\Roaming\\Python\\Python37\\site-packages\\tornado\\gen.py\", line 787, in inner\n      self.run()\n    File \"C:\\Users\\tuto\\AppData\\Roaming\\Python\\Python37\\site-packages\\tornado\\gen.py\", line 748, in run\n      yielded = self.gen.send(value)\n    File \"C:\\Users\\tuto\\AppData\\Roaming\\Python\\Python37\\site-packages\\ipykernel\\kernelbase.py\", line 365, in process_one\n      yield gen.maybe_future(dispatch(*args))\n    File \"C:\\Users\\tuto\\AppData\\Roaming\\Python\\Python37\\site-packages\\tornado\\gen.py\", line 209, in wrapper\n      yielded = next(result)\n    File \"C:\\Users\\tuto\\AppData\\Roaming\\Python\\Python37\\site-packages\\ipykernel\\kernelbase.py\", line 268, in dispatch_shell\n      yield gen.maybe_future(handler(stream, idents, msg))\n    File \"C:\\Users\\tuto\\AppData\\Roaming\\Python\\Python37\\site-packages\\tornado\\gen.py\", line 209, in wrapper\n      yielded = next(result)\n    File \"C:\\Users\\tuto\\AppData\\Roaming\\Python\\Python37\\site-packages\\ipykernel\\kernelbase.py\", line 545, in execute_request\n      user_expressions, allow_stdin,\n    File \"C:\\Users\\tuto\\AppData\\Roaming\\Python\\Python37\\site-packages\\tornado\\gen.py\", line 209, in wrapper\n      yielded = next(result)\n    File \"C:\\Users\\tuto\\AppData\\Roaming\\Python\\Python37\\site-packages\\ipykernel\\ipkernel.py\", line 300, in do_execute\n      res = shell.run_cell(code, store_history=store_history, silent=silent)\n    File \"C:\\Users\\tuto\\AppData\\Roaming\\Python\\Python37\\site-packages\\ipykernel\\zmqshell.py\", line 536, in run_cell\n      return super(ZMQInteractiveShell, self).run_cell(*args, **kwargs)\n    File \"C:\\Users\\tuto\\AppData\\Roaming\\Python\\Python37\\site-packages\\IPython\\core\\interactiveshell.py\", line 2858, in run_cell\n      raw_cell, store_history, silent, shell_futures)\n    File \"C:\\Users\\tuto\\AppData\\Roaming\\Python\\Python37\\site-packages\\IPython\\core\\interactiveshell.py\", line 2886, in _run_cell\n      return runner(coro)\n    File \"C:\\Users\\tuto\\AppData\\Roaming\\Python\\Python37\\site-packages\\IPython\\core\\async_helpers.py\", line 68, in _pseudo_sync_runner\n      coro.send(None)\n    File \"C:\\Users\\tuto\\AppData\\Roaming\\Python\\Python37\\site-packages\\IPython\\core\\interactiveshell.py\", line 3063, in run_cell_async\n      interactivity=interactivity, compiler=compiler, result=result)\n    File \"C:\\Users\\tuto\\AppData\\Roaming\\Python\\Python37\\site-packages\\IPython\\core\\interactiveshell.py\", line 3254, in run_ast_nodes\n      if (await self.run_code(code, result,  async_=asy)):\n    File \"C:\\Users\\tuto\\AppData\\Roaming\\Python\\Python37\\site-packages\\IPython\\core\\interactiveshell.py\", line 3331, in run_code\n      exec(code_obj, self.user_global_ns, self.user_ns)\n    File \"<ipython-input-6-cf7953a05327>\", line 1, in <module>\n      model.evaluate(test_ds)\n    File \"c:\\Users\\tuto\\AppData\\Local\\Programs\\Python\\Python37\\lib\\site-packages\\keras\\utils\\traceback_utils.py\", line 65, in error_handler\n      return fn(*args, **kwargs)\n    File \"c:\\Users\\tuto\\AppData\\Local\\Programs\\Python\\Python37\\lib\\site-packages\\keras\\engine\\training.py\", line 1947, in evaluate\n      tmp_logs = self.test_function(iterator)\n    File \"c:\\Users\\tuto\\AppData\\Local\\Programs\\Python\\Python37\\lib\\site-packages\\keras\\engine\\training.py\", line 1727, in test_function\n      return step_function(self, iterator)\n    File \"c:\\Users\\tuto\\AppData\\Local\\Programs\\Python\\Python37\\lib\\site-packages\\keras\\engine\\training.py\", line 1713, in step_function\n      outputs = model.distribute_strategy.run(run_step, args=(data,))\n    File \"c:\\Users\\tuto\\AppData\\Local\\Programs\\Python\\Python37\\lib\\site-packages\\keras\\engine\\training.py\", line 1701, in run_step\n      outputs = model.test_step(data)\n    File \"c:\\Users\\tuto\\AppData\\Local\\Programs\\Python\\Python37\\lib\\site-packages\\keras\\engine\\training.py\", line 1665, in test_step\n      y_pred = self(x, training=False)\n    File \"c:\\Users\\tuto\\AppData\\Local\\Programs\\Python\\Python37\\lib\\site-packages\\keras\\utils\\traceback_utils.py\", line 65, in error_handler\n      return fn(*args, **kwargs)\n    File \"c:\\Users\\tuto\\AppData\\Local\\Programs\\Python\\Python37\\lib\\site-packages\\keras\\engine\\training.py\", line 557, in __call__\n      return super().__call__(*args, **kwargs)\n    File \"c:\\Users\\tuto\\AppData\\Local\\Programs\\Python\\Python37\\lib\\site-packages\\keras\\utils\\traceback_utils.py\", line 65, in error_handler\n      return fn(*args, **kwargs)\n    File \"c:\\Users\\tuto\\AppData\\Local\\Programs\\Python\\Python37\\lib\\site-packages\\keras\\engine\\base_layer.py\", line 1097, in __call__\n      outputs = call_fn(inputs, *args, **kwargs)\n    File \"c:\\Users\\tuto\\AppData\\Local\\Programs\\Python\\Python37\\lib\\site-packages\\keras\\utils\\traceback_utils.py\", line 96, in error_handler\n      return fn(*args, **kwargs)\n    File \"c:\\Users\\tuto\\AppData\\Local\\Programs\\Python\\Python37\\lib\\site-packages\\keras\\engine\\functional.py\", line 510, in call\n      return self._run_internal_graph(inputs, training=training, mask=mask)\n    File \"c:\\Users\\tuto\\AppData\\Local\\Programs\\Python\\Python37\\lib\\site-packages\\keras\\engine\\functional.py\", line 667, in _run_internal_graph\n      outputs = node.layer(*args, **kwargs)\n    File \"c:\\Users\\tuto\\AppData\\Local\\Programs\\Python\\Python37\\lib\\site-packages\\keras\\utils\\traceback_utils.py\", line 65, in error_handler\n      return fn(*args, **kwargs)\n    File \"c:\\Users\\tuto\\AppData\\Local\\Programs\\Python\\Python37\\lib\\site-packages\\keras\\engine\\training.py\", line 557, in __call__\n      return super().__call__(*args, **kwargs)\n    File \"c:\\Users\\tuto\\AppData\\Local\\Programs\\Python\\Python37\\lib\\site-packages\\keras\\utils\\traceback_utils.py\", line 65, in error_handler\n      return fn(*args, **kwargs)\n    File \"c:\\Users\\tuto\\AppData\\Local\\Programs\\Python\\Python37\\lib\\site-packages\\keras\\engine\\base_layer.py\", line 1097, in __call__\n      outputs = call_fn(inputs, *args, **kwargs)\n    File \"c:\\Users\\tuto\\AppData\\Local\\Programs\\Python\\Python37\\lib\\site-packages\\keras\\utils\\traceback_utils.py\", line 96, in error_handler\n      return fn(*args, **kwargs)\n    File \"c:\\Users\\tuto\\AppData\\Local\\Programs\\Python\\Python37\\lib\\site-packages\\keras\\engine\\functional.py\", line 510, in call\n      return self._run_internal_graph(inputs, training=training, mask=mask)\n    File \"c:\\Users\\tuto\\AppData\\Local\\Programs\\Python\\Python37\\lib\\site-packages\\keras\\engine\\functional.py\", line 667, in _run_internal_graph\n      outputs = node.layer(*args, **kwargs)\n    File \"c:\\Users\\tuto\\AppData\\Local\\Programs\\Python\\Python37\\lib\\site-packages\\keras\\utils\\traceback_utils.py\", line 65, in error_handler\n      return fn(*args, **kwargs)\n    File \"c:\\Users\\tuto\\AppData\\Local\\Programs\\Python\\Python37\\lib\\site-packages\\keras\\engine\\base_layer.py\", line 1097, in __call__\n      outputs = call_fn(inputs, *args, **kwargs)\n    File \"c:\\Users\\tuto\\AppData\\Local\\Programs\\Python\\Python37\\lib\\site-packages\\keras\\utils\\traceback_utils.py\", line 96, in error_handler\n      return fn(*args, **kwargs)\n    File \"c:\\Users\\tuto\\AppData\\Local\\Programs\\Python\\Python37\\lib\\site-packages\\keras\\layers\\convolutional\\base_conv.py\", line 283, in call\n      outputs = self.convolution_op(inputs, self.kernel)\n    File \"c:\\Users\\tuto\\AppData\\Local\\Programs\\Python\\Python37\\lib\\site-packages\\keras\\layers\\convolutional\\base_conv.py\", line 262, in convolution_op\n      name=self.__class__.__name__,\nNode: 'model_7/xception/block1_conv1/Conv2D'\nDNN library is not found.\n\t [[{{node model_7/xception/block1_conv1/Conv2D}}]] [Op:__inference_test_function_5324]"
     ]
    }
   ],
   "source": [
    "model.evaluate(test_ds)"
   ]
  },
  {
   "cell_type": "code",
   "execution_count": 9,
   "metadata": {},
   "outputs": [],
   "source": [
    "path = './clothing-dataset-small-master/test/pants/c8d21106-bbdb-4e8d-83e4-bf3d14e54c16.jpg'\n"
   ]
  },
  {
   "cell_type": "code",
   "execution_count": 10,
   "metadata": {},
   "outputs": [],
   "source": [
    "img = load_img(path, target_size=(299,299)) "
   ]
  },
  {
   "cell_type": "code",
   "execution_count": 11,
   "metadata": {},
   "outputs": [],
   "source": [
    "import numpy as np"
   ]
  },
  {
   "cell_type": "code",
   "execution_count": 12,
   "metadata": {},
   "outputs": [
    {
     "data": {
      "text/plain": [
       "(1, 299, 299, 3)"
      ]
     },
     "execution_count": 12,
     "metadata": {},
     "output_type": "execute_result"
    }
   ],
   "source": [
    "x = np.array(img)\n",
    "X = np.array([x])\n",
    "X.shape"
   ]
  },
  {
   "cell_type": "code",
   "execution_count": 13,
   "metadata": {},
   "outputs": [],
   "source": [
    "X = preprocess_input(X)"
   ]
  },
  {
   "cell_type": "code",
   "execution_count": 16,
   "metadata": {},
   "outputs": [
    {
     "ename": "UnimplementedError",
     "evalue": "Graph execution error:\n\nDetected at node 'model_7/xception/block1_conv1/Conv2D' defined at (most recent call last):\n    File \"c:\\Users\\tuto\\AppData\\Local\\Programs\\Python\\Python37\\lib\\runpy.py\", line 193, in _run_module_as_main\n      \"__main__\", mod_spec)\n    File \"c:\\Users\\tuto\\AppData\\Local\\Programs\\Python\\Python37\\lib\\runpy.py\", line 85, in _run_code\n      exec(code, run_globals)\n    File \"C:\\Users\\tuto\\AppData\\Roaming\\Python\\Python37\\site-packages\\ipykernel_launcher.py\", line 16, in <module>\n      app.launch_new_instance()\n    File \"C:\\Users\\tuto\\AppData\\Roaming\\Python\\Python37\\site-packages\\traitlets\\config\\application.py\", line 664, in launch_instance\n      app.start()\n    File \"C:\\Users\\tuto\\AppData\\Roaming\\Python\\Python37\\site-packages\\ipykernel\\kernelapp.py\", line 597, in start\n      self.io_loop.start()\n    File \"C:\\Users\\tuto\\AppData\\Roaming\\Python\\Python37\\site-packages\\tornado\\platform\\asyncio.py\", line 149, in start\n      self.asyncio_loop.run_forever()\n    File \"c:\\Users\\tuto\\AppData\\Local\\Programs\\Python\\Python37\\lib\\asyncio\\base_events.py\", line 538, in run_forever\n      self._run_once()\n    File \"c:\\Users\\tuto\\AppData\\Local\\Programs\\Python\\Python37\\lib\\asyncio\\base_events.py\", line 1782, in _run_once\n      handle._run()\n    File \"c:\\Users\\tuto\\AppData\\Local\\Programs\\Python\\Python37\\lib\\asyncio\\events.py\", line 88, in _run\n      self._context.run(self._callback, *self._args)\n    File \"C:\\Users\\tuto\\AppData\\Roaming\\Python\\Python37\\site-packages\\tornado\\ioloop.py\", line 690, in <lambda>\n      lambda f: self._run_callback(functools.partial(callback, future))\n    File \"C:\\Users\\tuto\\AppData\\Roaming\\Python\\Python37\\site-packages\\tornado\\ioloop.py\", line 743, in _run_callback\n      ret = callback()\n    File \"C:\\Users\\tuto\\AppData\\Roaming\\Python\\Python37\\site-packages\\tornado\\gen.py\", line 787, in inner\n      self.run()\n    File \"C:\\Users\\tuto\\AppData\\Roaming\\Python\\Python37\\site-packages\\tornado\\gen.py\", line 748, in run\n      yielded = self.gen.send(value)\n    File \"C:\\Users\\tuto\\AppData\\Roaming\\Python\\Python37\\site-packages\\ipykernel\\kernelbase.py\", line 365, in process_one\n      yield gen.maybe_future(dispatch(*args))\n    File \"C:\\Users\\tuto\\AppData\\Roaming\\Python\\Python37\\site-packages\\tornado\\gen.py\", line 209, in wrapper\n      yielded = next(result)\n    File \"C:\\Users\\tuto\\AppData\\Roaming\\Python\\Python37\\site-packages\\ipykernel\\kernelbase.py\", line 268, in dispatch_shell\n      yield gen.maybe_future(handler(stream, idents, msg))\n    File \"C:\\Users\\tuto\\AppData\\Roaming\\Python\\Python37\\site-packages\\tornado\\gen.py\", line 209, in wrapper\n      yielded = next(result)\n    File \"C:\\Users\\tuto\\AppData\\Roaming\\Python\\Python37\\site-packages\\ipykernel\\kernelbase.py\", line 545, in execute_request\n      user_expressions, allow_stdin,\n    File \"C:\\Users\\tuto\\AppData\\Roaming\\Python\\Python37\\site-packages\\tornado\\gen.py\", line 209, in wrapper\n      yielded = next(result)\n    File \"C:\\Users\\tuto\\AppData\\Roaming\\Python\\Python37\\site-packages\\ipykernel\\ipkernel.py\", line 300, in do_execute\n      res = shell.run_cell(code, store_history=store_history, silent=silent)\n    File \"C:\\Users\\tuto\\AppData\\Roaming\\Python\\Python37\\site-packages\\ipykernel\\zmqshell.py\", line 536, in run_cell\n      return super(ZMQInteractiveShell, self).run_cell(*args, **kwargs)\n    File \"C:\\Users\\tuto\\AppData\\Roaming\\Python\\Python37\\site-packages\\IPython\\core\\interactiveshell.py\", line 2858, in run_cell\n      raw_cell, store_history, silent, shell_futures)\n    File \"C:\\Users\\tuto\\AppData\\Roaming\\Python\\Python37\\site-packages\\IPython\\core\\interactiveshell.py\", line 2886, in _run_cell\n      return runner(coro)\n    File \"C:\\Users\\tuto\\AppData\\Roaming\\Python\\Python37\\site-packages\\IPython\\core\\async_helpers.py\", line 68, in _pseudo_sync_runner\n      coro.send(None)\n    File \"C:\\Users\\tuto\\AppData\\Roaming\\Python\\Python37\\site-packages\\IPython\\core\\interactiveshell.py\", line 3063, in run_cell_async\n      interactivity=interactivity, compiler=compiler, result=result)\n    File \"C:\\Users\\tuto\\AppData\\Roaming\\Python\\Python37\\site-packages\\IPython\\core\\interactiveshell.py\", line 3254, in run_ast_nodes\n      if (await self.run_code(code, result,  async_=asy)):\n    File \"C:\\Users\\tuto\\AppData\\Roaming\\Python\\Python37\\site-packages\\IPython\\core\\interactiveshell.py\", line 3331, in run_code\n      exec(code_obj, self.user_global_ns, self.user_ns)\n    File \"<ipython-input-14-3b72b0b1b4e1>\", line 1, in <module>\n      pred = model.predict(X)\n    File \"c:\\Users\\tuto\\AppData\\Local\\Programs\\Python\\Python37\\lib\\site-packages\\keras\\utils\\traceback_utils.py\", line 65, in error_handler\n      return fn(*args, **kwargs)\n    File \"c:\\Users\\tuto\\AppData\\Local\\Programs\\Python\\Python37\\lib\\site-packages\\keras\\engine\\training.py\", line 2253, in predict\n      tmp_batch_outputs = self.predict_function(iterator)\n    File \"c:\\Users\\tuto\\AppData\\Local\\Programs\\Python\\Python37\\lib\\site-packages\\keras\\engine\\training.py\", line 2041, in predict_function\n      return step_function(self, iterator)\n    File \"c:\\Users\\tuto\\AppData\\Local\\Programs\\Python\\Python37\\lib\\site-packages\\keras\\engine\\training.py\", line 2027, in step_function\n      outputs = model.distribute_strategy.run(run_step, args=(data,))\n    File \"c:\\Users\\tuto\\AppData\\Local\\Programs\\Python\\Python37\\lib\\site-packages\\keras\\engine\\training.py\", line 2015, in run_step\n      outputs = model.predict_step(data)\n    File \"c:\\Users\\tuto\\AppData\\Local\\Programs\\Python\\Python37\\lib\\site-packages\\keras\\engine\\training.py\", line 1983, in predict_step\n      return self(x, training=False)\n    File \"c:\\Users\\tuto\\AppData\\Local\\Programs\\Python\\Python37\\lib\\site-packages\\keras\\utils\\traceback_utils.py\", line 65, in error_handler\n      return fn(*args, **kwargs)\n    File \"c:\\Users\\tuto\\AppData\\Local\\Programs\\Python\\Python37\\lib\\site-packages\\keras\\engine\\training.py\", line 557, in __call__\n      return super().__call__(*args, **kwargs)\n    File \"c:\\Users\\tuto\\AppData\\Local\\Programs\\Python\\Python37\\lib\\site-packages\\keras\\utils\\traceback_utils.py\", line 65, in error_handler\n      return fn(*args, **kwargs)\n    File \"c:\\Users\\tuto\\AppData\\Local\\Programs\\Python\\Python37\\lib\\site-packages\\keras\\engine\\base_layer.py\", line 1097, in __call__\n      outputs = call_fn(inputs, *args, **kwargs)\n    File \"c:\\Users\\tuto\\AppData\\Local\\Programs\\Python\\Python37\\lib\\site-packages\\keras\\utils\\traceback_utils.py\", line 96, in error_handler\n      return fn(*args, **kwargs)\n    File \"c:\\Users\\tuto\\AppData\\Local\\Programs\\Python\\Python37\\lib\\site-packages\\keras\\engine\\functional.py\", line 510, in call\n      return self._run_internal_graph(inputs, training=training, mask=mask)\n    File \"c:\\Users\\tuto\\AppData\\Local\\Programs\\Python\\Python37\\lib\\site-packages\\keras\\engine\\functional.py\", line 667, in _run_internal_graph\n      outputs = node.layer(*args, **kwargs)\n    File \"c:\\Users\\tuto\\AppData\\Local\\Programs\\Python\\Python37\\lib\\site-packages\\keras\\utils\\traceback_utils.py\", line 65, in error_handler\n      return fn(*args, **kwargs)\n    File \"c:\\Users\\tuto\\AppData\\Local\\Programs\\Python\\Python37\\lib\\site-packages\\keras\\engine\\training.py\", line 557, in __call__\n      return super().__call__(*args, **kwargs)\n    File \"c:\\Users\\tuto\\AppData\\Local\\Programs\\Python\\Python37\\lib\\site-packages\\keras\\utils\\traceback_utils.py\", line 65, in error_handler\n      return fn(*args, **kwargs)\n    File \"c:\\Users\\tuto\\AppData\\Local\\Programs\\Python\\Python37\\lib\\site-packages\\keras\\engine\\base_layer.py\", line 1097, in __call__\n      outputs = call_fn(inputs, *args, **kwargs)\n    File \"c:\\Users\\tuto\\AppData\\Local\\Programs\\Python\\Python37\\lib\\site-packages\\keras\\utils\\traceback_utils.py\", line 96, in error_handler\n      return fn(*args, **kwargs)\n    File \"c:\\Users\\tuto\\AppData\\Local\\Programs\\Python\\Python37\\lib\\site-packages\\keras\\engine\\functional.py\", line 510, in call\n      return self._run_internal_graph(inputs, training=training, mask=mask)\n    File \"c:\\Users\\tuto\\AppData\\Local\\Programs\\Python\\Python37\\lib\\site-packages\\keras\\engine\\functional.py\", line 667, in _run_internal_graph\n      outputs = node.layer(*args, **kwargs)\n    File \"c:\\Users\\tuto\\AppData\\Local\\Programs\\Python\\Python37\\lib\\site-packages\\keras\\utils\\traceback_utils.py\", line 65, in error_handler\n      return fn(*args, **kwargs)\n    File \"c:\\Users\\tuto\\AppData\\Local\\Programs\\Python\\Python37\\lib\\site-packages\\keras\\engine\\base_layer.py\", line 1097, in __call__\n      outputs = call_fn(inputs, *args, **kwargs)\n    File \"c:\\Users\\tuto\\AppData\\Local\\Programs\\Python\\Python37\\lib\\site-packages\\keras\\utils\\traceback_utils.py\", line 96, in error_handler\n      return fn(*args, **kwargs)\n    File \"c:\\Users\\tuto\\AppData\\Local\\Programs\\Python\\Python37\\lib\\site-packages\\keras\\layers\\convolutional\\base_conv.py\", line 283, in call\n      outputs = self.convolution_op(inputs, self.kernel)\n    File \"c:\\Users\\tuto\\AppData\\Local\\Programs\\Python\\Python37\\lib\\site-packages\\keras\\layers\\convolutional\\base_conv.py\", line 262, in convolution_op\n      name=self.__class__.__name__,\nNode: 'model_7/xception/block1_conv1/Conv2D'\nDNN library is not found.\n\t [[{{node model_7/xception/block1_conv1/Conv2D}}]] [Op:__inference_predict_function_6358]",
     "output_type": "error",
     "traceback": [
      "\u001b[1;31m---------------------------------------------------------------------------\u001b[0m",
      "\u001b[1;31mUnimplementedError\u001b[0m                        Traceback (most recent call last)",
      "\u001b[1;32m<ipython-input-16-3b72b0b1b4e1>\u001b[0m in \u001b[0;36m<module>\u001b[1;34m\u001b[0m\n\u001b[1;32m----> 1\u001b[1;33m \u001b[0mpred\u001b[0m \u001b[1;33m=\u001b[0m \u001b[0mmodel\u001b[0m\u001b[1;33m.\u001b[0m\u001b[0mpredict\u001b[0m\u001b[1;33m(\u001b[0m\u001b[0mX\u001b[0m\u001b[1;33m)\u001b[0m\u001b[1;33m\u001b[0m\u001b[1;33m\u001b[0m\u001b[0m\n\u001b[0m",
      "\u001b[1;32mc:\\Users\\tuto\\AppData\\Local\\Programs\\Python\\Python37\\lib\\site-packages\\keras\\utils\\traceback_utils.py\u001b[0m in \u001b[0;36merror_handler\u001b[1;34m(*args, **kwargs)\u001b[0m\n\u001b[0;32m     68\u001b[0m             \u001b[1;31m# To get the full stack trace, call:\u001b[0m\u001b[1;33m\u001b[0m\u001b[1;33m\u001b[0m\u001b[1;33m\u001b[0m\u001b[0m\n\u001b[0;32m     69\u001b[0m             \u001b[1;31m# `tf.debugging.disable_traceback_filtering()`\u001b[0m\u001b[1;33m\u001b[0m\u001b[1;33m\u001b[0m\u001b[1;33m\u001b[0m\u001b[0m\n\u001b[1;32m---> 70\u001b[1;33m             \u001b[1;32mraise\u001b[0m \u001b[0me\u001b[0m\u001b[1;33m.\u001b[0m\u001b[0mwith_traceback\u001b[0m\u001b[1;33m(\u001b[0m\u001b[0mfiltered_tb\u001b[0m\u001b[1;33m)\u001b[0m \u001b[1;32mfrom\u001b[0m \u001b[1;32mNone\u001b[0m\u001b[1;33m\u001b[0m\u001b[1;33m\u001b[0m\u001b[0m\n\u001b[0m\u001b[0;32m     71\u001b[0m         \u001b[1;32mfinally\u001b[0m\u001b[1;33m:\u001b[0m\u001b[1;33m\u001b[0m\u001b[1;33m\u001b[0m\u001b[0m\n\u001b[0;32m     72\u001b[0m             \u001b[1;32mdel\u001b[0m \u001b[0mfiltered_tb\u001b[0m\u001b[1;33m\u001b[0m\u001b[1;33m\u001b[0m\u001b[0m\n",
      "\u001b[1;32mc:\\Users\\tuto\\AppData\\Local\\Programs\\Python\\Python37\\lib\\site-packages\\tensorflow\\python\\eager\\execute.py\u001b[0m in \u001b[0;36mquick_execute\u001b[1;34m(op_name, num_outputs, inputs, attrs, ctx, name)\u001b[0m\n\u001b[0;32m     53\u001b[0m     \u001b[0mctx\u001b[0m\u001b[1;33m.\u001b[0m\u001b[0mensure_initialized\u001b[0m\u001b[1;33m(\u001b[0m\u001b[1;33m)\u001b[0m\u001b[1;33m\u001b[0m\u001b[1;33m\u001b[0m\u001b[0m\n\u001b[0;32m     54\u001b[0m     tensors = pywrap_tfe.TFE_Py_Execute(ctx._handle, device_name, op_name,\n\u001b[1;32m---> 55\u001b[1;33m                                         inputs, attrs, num_outputs)\n\u001b[0m\u001b[0;32m     56\u001b[0m   \u001b[1;32mexcept\u001b[0m \u001b[0mcore\u001b[0m\u001b[1;33m.\u001b[0m\u001b[0m_NotOkStatusException\u001b[0m \u001b[1;32mas\u001b[0m \u001b[0me\u001b[0m\u001b[1;33m:\u001b[0m\u001b[1;33m\u001b[0m\u001b[1;33m\u001b[0m\u001b[0m\n\u001b[0;32m     57\u001b[0m     \u001b[1;32mif\u001b[0m \u001b[0mname\u001b[0m \u001b[1;32mis\u001b[0m \u001b[1;32mnot\u001b[0m \u001b[1;32mNone\u001b[0m\u001b[1;33m:\u001b[0m\u001b[1;33m\u001b[0m\u001b[1;33m\u001b[0m\u001b[0m\n",
      "\u001b[1;31mUnimplementedError\u001b[0m: Graph execution error:\n\nDetected at node 'model_7/xception/block1_conv1/Conv2D' defined at (most recent call last):\n    File \"c:\\Users\\tuto\\AppData\\Local\\Programs\\Python\\Python37\\lib\\runpy.py\", line 193, in _run_module_as_main\n      \"__main__\", mod_spec)\n    File \"c:\\Users\\tuto\\AppData\\Local\\Programs\\Python\\Python37\\lib\\runpy.py\", line 85, in _run_code\n      exec(code, run_globals)\n    File \"C:\\Users\\tuto\\AppData\\Roaming\\Python\\Python37\\site-packages\\ipykernel_launcher.py\", line 16, in <module>\n      app.launch_new_instance()\n    File \"C:\\Users\\tuto\\AppData\\Roaming\\Python\\Python37\\site-packages\\traitlets\\config\\application.py\", line 664, in launch_instance\n      app.start()\n    File \"C:\\Users\\tuto\\AppData\\Roaming\\Python\\Python37\\site-packages\\ipykernel\\kernelapp.py\", line 597, in start\n      self.io_loop.start()\n    File \"C:\\Users\\tuto\\AppData\\Roaming\\Python\\Python37\\site-packages\\tornado\\platform\\asyncio.py\", line 149, in start\n      self.asyncio_loop.run_forever()\n    File \"c:\\Users\\tuto\\AppData\\Local\\Programs\\Python\\Python37\\lib\\asyncio\\base_events.py\", line 538, in run_forever\n      self._run_once()\n    File \"c:\\Users\\tuto\\AppData\\Local\\Programs\\Python\\Python37\\lib\\asyncio\\base_events.py\", line 1782, in _run_once\n      handle._run()\n    File \"c:\\Users\\tuto\\AppData\\Local\\Programs\\Python\\Python37\\lib\\asyncio\\events.py\", line 88, in _run\n      self._context.run(self._callback, *self._args)\n    File \"C:\\Users\\tuto\\AppData\\Roaming\\Python\\Python37\\site-packages\\tornado\\ioloop.py\", line 690, in <lambda>\n      lambda f: self._run_callback(functools.partial(callback, future))\n    File \"C:\\Users\\tuto\\AppData\\Roaming\\Python\\Python37\\site-packages\\tornado\\ioloop.py\", line 743, in _run_callback\n      ret = callback()\n    File \"C:\\Users\\tuto\\AppData\\Roaming\\Python\\Python37\\site-packages\\tornado\\gen.py\", line 787, in inner\n      self.run()\n    File \"C:\\Users\\tuto\\AppData\\Roaming\\Python\\Python37\\site-packages\\tornado\\gen.py\", line 748, in run\n      yielded = self.gen.send(value)\n    File \"C:\\Users\\tuto\\AppData\\Roaming\\Python\\Python37\\site-packages\\ipykernel\\kernelbase.py\", line 365, in process_one\n      yield gen.maybe_future(dispatch(*args))\n    File \"C:\\Users\\tuto\\AppData\\Roaming\\Python\\Python37\\site-packages\\tornado\\gen.py\", line 209, in wrapper\n      yielded = next(result)\n    File \"C:\\Users\\tuto\\AppData\\Roaming\\Python\\Python37\\site-packages\\ipykernel\\kernelbase.py\", line 268, in dispatch_shell\n      yield gen.maybe_future(handler(stream, idents, msg))\n    File \"C:\\Users\\tuto\\AppData\\Roaming\\Python\\Python37\\site-packages\\tornado\\gen.py\", line 209, in wrapper\n      yielded = next(result)\n    File \"C:\\Users\\tuto\\AppData\\Roaming\\Python\\Python37\\site-packages\\ipykernel\\kernelbase.py\", line 545, in execute_request\n      user_expressions, allow_stdin,\n    File \"C:\\Users\\tuto\\AppData\\Roaming\\Python\\Python37\\site-packages\\tornado\\gen.py\", line 209, in wrapper\n      yielded = next(result)\n    File \"C:\\Users\\tuto\\AppData\\Roaming\\Python\\Python37\\site-packages\\ipykernel\\ipkernel.py\", line 300, in do_execute\n      res = shell.run_cell(code, store_history=store_history, silent=silent)\n    File \"C:\\Users\\tuto\\AppData\\Roaming\\Python\\Python37\\site-packages\\ipykernel\\zmqshell.py\", line 536, in run_cell\n      return super(ZMQInteractiveShell, self).run_cell(*args, **kwargs)\n    File \"C:\\Users\\tuto\\AppData\\Roaming\\Python\\Python37\\site-packages\\IPython\\core\\interactiveshell.py\", line 2858, in run_cell\n      raw_cell, store_history, silent, shell_futures)\n    File \"C:\\Users\\tuto\\AppData\\Roaming\\Python\\Python37\\site-packages\\IPython\\core\\interactiveshell.py\", line 2886, in _run_cell\n      return runner(coro)\n    File \"C:\\Users\\tuto\\AppData\\Roaming\\Python\\Python37\\site-packages\\IPython\\core\\async_helpers.py\", line 68, in _pseudo_sync_runner\n      coro.send(None)\n    File \"C:\\Users\\tuto\\AppData\\Roaming\\Python\\Python37\\site-packages\\IPython\\core\\interactiveshell.py\", line 3063, in run_cell_async\n      interactivity=interactivity, compiler=compiler, result=result)\n    File \"C:\\Users\\tuto\\AppData\\Roaming\\Python\\Python37\\site-packages\\IPython\\core\\interactiveshell.py\", line 3254, in run_ast_nodes\n      if (await self.run_code(code, result,  async_=asy)):\n    File \"C:\\Users\\tuto\\AppData\\Roaming\\Python\\Python37\\site-packages\\IPython\\core\\interactiveshell.py\", line 3331, in run_code\n      exec(code_obj, self.user_global_ns, self.user_ns)\n    File \"<ipython-input-14-3b72b0b1b4e1>\", line 1, in <module>\n      pred = model.predict(X)\n    File \"c:\\Users\\tuto\\AppData\\Local\\Programs\\Python\\Python37\\lib\\site-packages\\keras\\utils\\traceback_utils.py\", line 65, in error_handler\n      return fn(*args, **kwargs)\n    File \"c:\\Users\\tuto\\AppData\\Local\\Programs\\Python\\Python37\\lib\\site-packages\\keras\\engine\\training.py\", line 2253, in predict\n      tmp_batch_outputs = self.predict_function(iterator)\n    File \"c:\\Users\\tuto\\AppData\\Local\\Programs\\Python\\Python37\\lib\\site-packages\\keras\\engine\\training.py\", line 2041, in predict_function\n      return step_function(self, iterator)\n    File \"c:\\Users\\tuto\\AppData\\Local\\Programs\\Python\\Python37\\lib\\site-packages\\keras\\engine\\training.py\", line 2027, in step_function\n      outputs = model.distribute_strategy.run(run_step, args=(data,))\n    File \"c:\\Users\\tuto\\AppData\\Local\\Programs\\Python\\Python37\\lib\\site-packages\\keras\\engine\\training.py\", line 2015, in run_step\n      outputs = model.predict_step(data)\n    File \"c:\\Users\\tuto\\AppData\\Local\\Programs\\Python\\Python37\\lib\\site-packages\\keras\\engine\\training.py\", line 1983, in predict_step\n      return self(x, training=False)\n    File \"c:\\Users\\tuto\\AppData\\Local\\Programs\\Python\\Python37\\lib\\site-packages\\keras\\utils\\traceback_utils.py\", line 65, in error_handler\n      return fn(*args, **kwargs)\n    File \"c:\\Users\\tuto\\AppData\\Local\\Programs\\Python\\Python37\\lib\\site-packages\\keras\\engine\\training.py\", line 557, in __call__\n      return super().__call__(*args, **kwargs)\n    File \"c:\\Users\\tuto\\AppData\\Local\\Programs\\Python\\Python37\\lib\\site-packages\\keras\\utils\\traceback_utils.py\", line 65, in error_handler\n      return fn(*args, **kwargs)\n    File \"c:\\Users\\tuto\\AppData\\Local\\Programs\\Python\\Python37\\lib\\site-packages\\keras\\engine\\base_layer.py\", line 1097, in __call__\n      outputs = call_fn(inputs, *args, **kwargs)\n    File \"c:\\Users\\tuto\\AppData\\Local\\Programs\\Python\\Python37\\lib\\site-packages\\keras\\utils\\traceback_utils.py\", line 96, in error_handler\n      return fn(*args, **kwargs)\n    File \"c:\\Users\\tuto\\AppData\\Local\\Programs\\Python\\Python37\\lib\\site-packages\\keras\\engine\\functional.py\", line 510, in call\n      return self._run_internal_graph(inputs, training=training, mask=mask)\n    File \"c:\\Users\\tuto\\AppData\\Local\\Programs\\Python\\Python37\\lib\\site-packages\\keras\\engine\\functional.py\", line 667, in _run_internal_graph\n      outputs = node.layer(*args, **kwargs)\n    File \"c:\\Users\\tuto\\AppData\\Local\\Programs\\Python\\Python37\\lib\\site-packages\\keras\\utils\\traceback_utils.py\", line 65, in error_handler\n      return fn(*args, **kwargs)\n    File \"c:\\Users\\tuto\\AppData\\Local\\Programs\\Python\\Python37\\lib\\site-packages\\keras\\engine\\training.py\", line 557, in __call__\n      return super().__call__(*args, **kwargs)\n    File \"c:\\Users\\tuto\\AppData\\Local\\Programs\\Python\\Python37\\lib\\site-packages\\keras\\utils\\traceback_utils.py\", line 65, in error_handler\n      return fn(*args, **kwargs)\n    File \"c:\\Users\\tuto\\AppData\\Local\\Programs\\Python\\Python37\\lib\\site-packages\\keras\\engine\\base_layer.py\", line 1097, in __call__\n      outputs = call_fn(inputs, *args, **kwargs)\n    File \"c:\\Users\\tuto\\AppData\\Local\\Programs\\Python\\Python37\\lib\\site-packages\\keras\\utils\\traceback_utils.py\", line 96, in error_handler\n      return fn(*args, **kwargs)\n    File \"c:\\Users\\tuto\\AppData\\Local\\Programs\\Python\\Python37\\lib\\site-packages\\keras\\engine\\functional.py\", line 510, in call\n      return self._run_internal_graph(inputs, training=training, mask=mask)\n    File \"c:\\Users\\tuto\\AppData\\Local\\Programs\\Python\\Python37\\lib\\site-packages\\keras\\engine\\functional.py\", line 667, in _run_internal_graph\n      outputs = node.layer(*args, **kwargs)\n    File \"c:\\Users\\tuto\\AppData\\Local\\Programs\\Python\\Python37\\lib\\site-packages\\keras\\utils\\traceback_utils.py\", line 65, in error_handler\n      return fn(*args, **kwargs)\n    File \"c:\\Users\\tuto\\AppData\\Local\\Programs\\Python\\Python37\\lib\\site-packages\\keras\\engine\\base_layer.py\", line 1097, in __call__\n      outputs = call_fn(inputs, *args, **kwargs)\n    File \"c:\\Users\\tuto\\AppData\\Local\\Programs\\Python\\Python37\\lib\\site-packages\\keras\\utils\\traceback_utils.py\", line 96, in error_handler\n      return fn(*args, **kwargs)\n    File \"c:\\Users\\tuto\\AppData\\Local\\Programs\\Python\\Python37\\lib\\site-packages\\keras\\layers\\convolutional\\base_conv.py\", line 283, in call\n      outputs = self.convolution_op(inputs, self.kernel)\n    File \"c:\\Users\\tuto\\AppData\\Local\\Programs\\Python\\Python37\\lib\\site-packages\\keras\\layers\\convolutional\\base_conv.py\", line 262, in convolution_op\n      name=self.__class__.__name__,\nNode: 'model_7/xception/block1_conv1/Conv2D'\nDNN library is not found.\n\t [[{{node model_7/xception/block1_conv1/Conv2D}}]] [Op:__inference_predict_function_6358]"
     ]
    }
   ],
   "source": [
    "pred = model.predict(X)"
   ]
  },
  {
   "cell_type": "code",
   "execution_count": null,
   "metadata": {},
   "outputs": [],
   "source": [
    "classes =['dress',\n",
    " 'hat',\n",
    " 'longsleeve',\n",
    " 'outwear',\n",
    " 'pants',\n",
    " 'shirt',\n",
    " 'shoes',\n",
    " 'shorts',\n",
    " 'skirt',\n",
    " 't-shirt']"
   ]
  },
  {
   "cell_type": "code",
   "execution_count": null,
   "metadata": {},
   "outputs": [],
   "source": [
    "dict(zip(classes,pred[0]))"
   ]
  }
 ],
 "metadata": {
  "kernelspec": {
   "display_name": "Python 3.7.6 64-bit",
   "language": "python",
   "name": "python3"
  },
  "language_info": {
   "codemirror_mode": {
    "name": "ipython",
    "version": 3
   },
   "file_extension": ".py",
   "mimetype": "text/x-python",
   "name": "python",
   "nbconvert_exporter": "python",
   "pygments_lexer": "ipython3",
   "version": "3.7.6"
  },
  "orig_nbformat": 4,
  "vscode": {
   "interpreter": {
    "hash": "46327b6bb16798f80635706720d32319bb9fd65aa2f1c2afb04f8d6b7da62462"
   }
  }
 },
 "nbformat": 4,
 "nbformat_minor": 2
}
